start!
Traceback (most recent call last):
  File "../koding/baseline_word2vec.py", line 355, in <module>
    main()
  File "../koding/baseline_word2vec.py", line 327, in main
    sep = '\t', header=None, names = ['label', 'score', 'text'])
  File "/home/cusp/rn1041/.conda/envs/py27/lib/python2.7/site-packages/pandas/io/parsers.py", line 498, in parser_f
    return _read(filepath_or_buffer, kwds)
  File "/home/cusp/rn1041/.conda/envs/py27/lib/python2.7/site-packages/pandas/io/parsers.py", line 275, in _read
    parser = TextFileReader(filepath_or_buffer, **kwds)
  File "/home/cusp/rn1041/.conda/envs/py27/lib/python2.7/site-packages/pandas/io/parsers.py", line 590, in __init__
    self._make_engine(self.engine)
  File "/home/cusp/rn1041/.conda/envs/py27/lib/python2.7/site-packages/pandas/io/parsers.py", line 731, in _make_engine
    self._engine = CParserWrapper(self.f, **self.options)
  File "/home/cusp/rn1041/.conda/envs/py27/lib/python2.7/site-packages/pandas/io/parsers.py", line 1103, in __init__
    self._reader = _parser.TextReader(src, **kwds)
  File "pandas/parser.pyx", line 353, in pandas.parser.TextReader.__cinit__ (pandas/parser.c:3246)
  File "pandas/parser.pyx", line 591, in pandas.parser.TextReader._setup_parser_source (pandas/parser.c:6111)
IOError: File /gpfs1/cusp/rn1041/snlp/reddit/koding/data/train2.txt does not exist
